Workbook

Sheet Read Me
A1: Arab Bank – EWRA Platform: Inherent and Residual Risk Rating Calculator
A2: Companion to the EWRA Platform Scope Document v1.0 (§7 taxonomy, §8 inherent risk methodology, §12 risk appetite). Classification: Confidential – Internal Use Only.
A4: Purpose | B4: Calculates the inherent risk rating (before controls) for all 20 Level-1 risks across 30 group entities, using the two methods in Scope Document §8: a factor-based model for financial-crime risks (FC-01 to FC-07) and a likelihood × impact model for regulatory and enterprise risks (RC-01 to ER-09).
A5: Status of data | B5: All entity data, indicator values and likelihood/impact scores are ILLUSTRATIVE SAMPLE DATA for design and testing. Entity names, tiers and thresholds are proposed defaults to be confirmed by Group Compliance and Group Risk during Discovery.
A6: Calculation flow | B6: 1. Config sets scales, bands, aggregation method and LxI parameters. 2. Factor Weights sets the 5 factor weights per FC risk. 3. Indicators holds the indicator library, score thresholds and per-risk indicator weights. 4. Indicator Data holds raw values per entity. 5. Indicator Scores converts each value to a 1–5 score. 6. FC Calculation builds factor scores and the inherent score for 7 FC risks × 30 entities. 7. LxI Assessment scores 13 risks × 30 entities. 8. Inherent Summary, Dashboard and Checks consolidate and validate.
A7: Factor model | B7: Indicator score: 1 if below the 'Score 2 from' threshold, rising by one for each threshold met (max 5). Factor score = weighted average of indicator scores within the factor (indicator weights are relative, per risk; indicators with no data are excluded and the remainder reweighted, unless Config says otherwise). Inherent score = Σ factor weight × factor score, then the Config aggregation method is applied (weighted average, weighted with floor, or maximum).
A8: Floor rule | B8: With 'Weighted with floor', if any single factor scores at or above the trigger (default 5), the inherent score cannot be below the floor (default 4.00 = Medium-High). This stops one severe factor being averaged away.
A9: LxI model | B9: Impact = highest of the four impact dimensions (or weighted average, per Config). Inherent product = Likelihood × Impact (1–25), mapped to the 5-point scale using the L×I bands in Config. RC-04 Shariah applies only to entities flagged Islamic.
A10: Overrides | B10: A calculated rating may be moved by up to the Config maximum (default ±1 notch). The override applies only when 'HO approval' = Y, matching the maker-checker rule in Scope Document §8.4 and §13.4. Every override needs a justification.
A11: Residual model | B11: Residual = inherent exposure after tested controls (§10). Each control's effective rating (CE) is the worse of design and operating effectiveness from its latest test. A test counts only if Head Office accepted the evidence and it is not overdue; otherwise CE = 4 (Ineffective, 0% credit). Control environment per risk = contribution-weighted average CE of mapped, applicable controls, capped at Partially effective if any key control is Ineffective, and Ineffective if no key control applies.
A12: Residual methods | B12: Matrix (default): residual looked up from the inherent rating × control environment matrix in Residual Config. Numeric: residual score = inherent score × (1 − weighted mitigation credit), never more than 2 notches below inherent. Switch in Residual Config.
A13: Testing and evidence | B13: Control Testing holds one row per entity and control: owner, independent tester, design rating, test date, type, sample size vs §11.3 minimum, exceptions, result, evidence reference and HO evidence review. Next-test-due follows the §11.1 frequency table by tier, key flag and last result.
A14: Appetite | B14: Final residual rating is compared with each risk's maximum acceptable residual rating (§12): Within, Amber (one notch above) or Red (two or more notches above; optionally any excess on a zero-tolerance risk), with the §12.4 escalation route.
A15: Colour legend | B15: Blue text on light-yellow fill = input you may edit. Black text = formula, do not edit. Green text = link to another sheet. Rating colours: green Low, light green Medium-Low, yellow Medium, orange Medium-High, red High.
A17: Sheet | B17: What it holds | C17: Edit?
A18: Config | B18: Rating scale, score bands, aggregation method, missing-data rule, LxI parameters, override limit | C18: Yes – yellow cells
A19: Entities | B19: 30 group entities with region, type, tier, Islamic flag and aggregation weight | C19: Yes – yellow cells
A20: Risk Taxonomy | B20: 20 Level-1 risks, domain, method, owner and appetite reference | C20: Reference
A21: Factor Weights | B21: Factor weights for the 7 financial-crime risks (each row must total 100%) | C21: Yes – yellow cells
A22: Indicators | B22: 31 indicators: factor, unit, source, direction, thresholds and relative weight per FC risk | C22: Yes – yellow cells
A23: Indicator Data | B23: Raw indicator values for each entity (one column per entity) | C23: Yes – yellow cells
A24: Indicator Scores | B24: 1–5 score for every indicator and entity | C24: No – formulas
A25: FC Calculation | B25: Factor scores, inherent score and rating for 7 FC risks × 30 entities, with overrides | C25: Override columns only
A26: LxI Assessment | B26: Likelihood, impact dimensions, product and rating for 13 risks × 30 entities, with overrides | C26: Yellow cells
A27: Inherent Summary | B27: Heat map of final inherent rating: 30 entities × 20 risks, with group averages | C27: No – formulas
A28: Inherent Dashboard | B28: Headline figures and charts of group inherent risk | C28: No – formulas
... A38: Checks | B38: Validation of inherent and residual configuration, coverage, testing, overrides and appetite | C38: No – formulas

Sheet Config
A1: Configuration
A2: Head Office Administrator settings. Changes here flow through every calculation. Yellow cells are editable.
A3: 1. Rating scale and score bands | H3: Lists (used by drop-downs)
A4: Score | B4: Rating | C4: Colour | D4: Factor model: inherent score from | E4: L×I model: product from
A5: 1 | B5: Low | C5: Green | D5: 1 | E5: 1 | H5: Weighted average
A6: 2 | B6: Medium-Low | C6: Light green | D6: 1.81 | E6: 5 | H6: Weighted with floor
A7: 3 | B7: Medium | C7: Amber | D7: 2.61 | E7: 9 | H7: Maximum (worst-of)
A8: 4 | B8: Medium-High | C8: Orange | D8: 3.41 | E8: 13
A9: 5 | B9: High | C9: Red | D9: 4.21 | E9: 20 | H9: Exclude and reweight
H10: Score as High (5)
A11: 2. Factor model (FC-01 to FC-07)
A12: Aggregation method | C12: Weighted with floor | D12: Weighted average | Weighted with floor | Maximum (worst-of). Scope Document §8.4. | H12: Highest dimension
A13: Floor trigger: any factor score at or above | C13: 5 | D13: Used only with 'Weighted with floor'. | H13: Weighted average
A14: Floor: minimum inherent score when triggered | C14: 4 | D14: Default 4.00 = Medium-High.
A15: Missing indicator data | C15: Exclude and reweight | D15: Exclude and reweight | Score as High (5). Conservative option scores missing data as 5. | H15: Y
H16: N
A18: 3. Likelihood × impact model (RC-01 to ER-09) | H18: Customer
A19: Impact aggregation | C19: Highest dimension | D19: Highest dimension | Weighted average. Scope Document §8.3 default is highest dimension. | H19: Geography
A20: Financial impact weight | C20: 0.35 | H20: Products & services
A21: Regulatory impact weight | C21: 0.3 | H21: Delivery channels
A22: Reputational impact weight | C22: 0.2 | H22: Transactions & volumes
A23: Customer / operational impact weight | C23: 0.15
A24: Total (must be 100%) | C24: =SUM(C20:C23) -> 1 | D24: Used only with 'Weighted average'. Proposed default weights. | H24: Higher = riskier
H25: Lower = riskier
A26: 4. Override governance
A27: Maximum override (notches) | C27: 1 | D27: Scope Document §8.4: up to one notch, with justification and HO approval.

Sheet Entities
A1: Entity register (illustrative – confirm in Discovery)
A2: Per Scope Document §5.3–5.5. Aggregation weight drives the group weighted average (default: Tier 1 = 3, Tier 2 = 2, Tier 3 = 1).
A4: Entity code | B4: Entity | C4: Country | D4: Region | E4: Entity type | F4: Tier | G4: Islamic (Y/N) | H4: Profile (sample data only) | I4: Aggregation weight
A5: JO-HO | B5: Arab Bank plc – Jordan (HO and domestic network) | C5: Jordan | D5: Jordan (home) | E5: Head Office / branches | F5: Tier 1 | G5: N | H5: Medium | I5: 3
A6: JO-IIAB | B6: Islamic International Arab Bank | C6: Jordan | D6: Jordan (home) | E6: Subsidiary – Islamic bank | F6: Tier 1 | G6: Y | H6: Medium | I6: 3
A7: JO-INV | B7: Al-Arabi Investment Group (AB Invest) | C7: Jordan | D7: Jordan (home) | E7: Subsidiary – investment | F7: Tier 3 | G7: N | H7: Medium | I7: 1
A8: JO-INS | B8: Insurance subsidiary – Jordan | C8: Jordan | D8: Jordan (home) | E8: Subsidiary – insurance | F8: Tier 3 | G8: N | H8: Medium | I8: 1
A9: JO-LSG | B9: Leasing subsidiary – Jordan | C9: Jordan | D9: Jordan (home) | E9: Subsidiary – leasing | F9: Tier 3 | G9: N | H9: Medium | I9: 1
A10: PS | B10: Arab Bank – Palestine | C10: Palestine | D10: Levant | E10: Foreign branch | F10: Tier 1 | G10: N | H10: Higher | I10: 3
A11: PS-INV | B11: Al-Arabi Investment Group – Palestine | C11: Palestine | D11: Levant | E11: Subsidiary – investment | F11: Tier 3 | G11: N | H11: Higher | I11: 1
A12: LB | B12: Arab Bank – Lebanon | C12: Lebanon | D12: Levant | E12: Foreign branch | F12: Tier 2 | G12: N | H12: Higher | I12: 2
A13: SY | B13: Arab Bank – Syria | C13: Syria | D13: Levant | E13: Subsidiary – bank | F13: Tier 2 | G13: N | H13: Higher | I13: 2
A14: AE | B14: Arab Bank – UAE | C14: UAE | D14: GCC | E14: Foreign branch | F14: Tier 1 | G14: N | H14: Medium | I14: 3
A15: BH | B15: Arab Bank – Bahrain | C15: Bahrain | D15: GCC | E15: Foreign branch | F15: Tier 2 | G15: N | H15: Medium | I15: 2
A16: QA | B16: Arab Bank – Qatar | C16: Qatar | D16: GCC | E16: Foreign branch | F16: Tier 2 | G16: N | H16: Medium | I16: 2
... A34: US | B34: Arab Bank – United States (if retained) | C34: United States | D34: Americas | E34: Foreign branch | F34: Tier 3 | G34: N | H34: Lower | I34: 1

Sheet Risk Taxonomy
A1: Level-1 risk taxonomy
A2: Scope Document §7 (taxonomy) and §12 (appetite). Appetite applies to residual risk and is shown here for reference.
A4: Code | B4: Level-1 risk | C4: Domain | D4: Inherent method | E4: Group owner | F4: Applies to | G4: Appetite level | H4: Max acceptable residual rating
A5: FC-01 | B5: Money laundering | C5: A – Financial crime | D5: Factor-based | E5: Group MLRO | F5: All entities | G5: Very low | H5: Medium-Low
A6: FC-02 | B6: Terrorist financing | C6: A – Financial crime | D6: Factor-based | E6: Group MLRO | F6: All entities | G6: Zero tolerance | H6: Low
A7: FC-03 | B7: Proliferation financing | C7: A – Financial crime | D7: Factor-based | E7: Group MLRO | F7: All entities | G7: Zero tolerance | H7: Low
A8: FC-04 | B8: Sanctions | C8: A – Financial crime | D8: Factor-based | E8: Head of Group Sanctions | F8: All entities | G8: Zero tolerance | H8: Low
A9: FC-05 | B9: Bribery and corruption | C9: A – Financial crime | D9: Factor-based | E9: Group CCO | F9: All entities | G9: Zero tolerance | H9: Low
A10: FC-06 | B10: Fraud | C10: A – Financial crime | D10: Factor-based | E10: Head of Fraud Risk | F10: All entities | G10: Low | H10: Medium
A11: FC-07 | B11: Tax evasion and tax transparency | C11: A – Financial crime | D11: Factor-based | E11: Group CCO | F11: All entities | G11: Zero tolerance (facilitation) | H11: Low
A12: RC-01 | B12: Regulatory compliance | C12: B – Regulatory and conduct | D12: Likelihood × impact | E12: Group CCO | F12: All entities | G12: Very low | H12: Medium-Low
A13: RC-02 | B13: Conduct and consumer protection | C13: B – Regulatory and conduct | D13: Likelihood × impact | E13: Group CCO | F13: All entities | G13: Low | H13: Medium
A14: RC-03 | B14: Data protection and privacy | C14: B – Regulatory and conduct | D14: Likelihood × impact | E14: Group DPO | F14: All entities | G14: Very low | H14: Medium-Low
A15: RC-04 | B15: Shariah non-compliance | C15: B – Regulatory and conduct | D15: Likelihood × impact | E15: Shariah Supervisory Board Secretary | F15: Islamic entities only | G15: Very low | H15: Medium-Low
... A24: ER-09 | B24: Strategic, business model and ESG | C24: C – Enterprise | D24: Likelihood × impact | E24: Group Head of Strategy / Sustainability | F24: All entities | G24: Moderate | H24: Medium-High

Sheet Factor Weights
A1: Factor weights – financial-crime risks
A2: Scope Document §8.2. Each row must total 100%; the ML row is the documented default, other rows are proposed defaults.
A4: Code | B4: Risk | C4: Customer | D4: Geography | E4: Products & services | F4: Delivery channels | G4: Transactions & volumes | H4: Total | I4: Check
A5: FC-01 | B5: Money laundering | C5: 0.3 | D5: 0.25 | E5: 0.2 | F5: 0.15 | G5: 0.1 | H5: =SUM(C5:G5) -> 1 | I5: =IF(ROUND(H5,4)=1,"OK","Must total 100%") -> OK
A6: FC-02 | B6: Terrorist financing | C6: 0.25 | D6: 0.3 | E6: 0.15 | F6: 0.1 | G6: 0.2 | H6: =SUM(C6:G6) -> 1 | I6: =IF(ROUND(H6,4)=1,"OK","Must total 100%") -> OK
A7: FC-03 | B7: Proliferation financing | C7: 0.15 | D7: 0.3 | E7: 0.3 | F7: 0.05 | G7: 0.2 | H7: =SUM(C7:G7) -> 1 | I7: =IF(ROUND(H7,4)=1,"OK","Must total 100%") -> OK
A8: FC-04 | B8: Sanctions | C8: 0.15 | D8: 0.4 | E8: 0.2 | F8: 0.05 | G8: 0.2 | H8: =SUM(C8:G8) -> 1 | I8: =IF(ROUND(H8,4)=1,"OK","Must total 100%") -> OK
A9: FC-05 | B9: Bribery and corruption | C9: 0.3 | D9: 0.25 | E9: 0.15 | F9: 0.2 | G9: 0.1 | H9: =SUM(C9:G9) -> 1 | I9: =IF(ROUND(H9,4)=1,"OK","Must total 100%") -> OK
A10: FC-06 | B10: Fraud | C10: 0.2 | D10: 0.1 | E10: 0.2 | F10: 0.3 | G10: 0.2 | H10: =SUM(C10:G10) -> 1 | I10: =IF(ROUND(H10,4)=1,"OK","Must total 100%") -> OK
A11: FC-07 | B11: Tax evasion and tax transparency | C11: 0.35 | D11: 0.25 | E11: 0.2 | F11: 0.1 | G11: 0.1 | H11: =SUM(C11:G11) -> 1 | I11: =IF(ROUND(H11,4)=1,"OK","Must total 100%") -> OK

Sheet Indicators
A1: Indicator library, scoring thresholds and per-risk weights
A2: Score = 1 below 'Score 2 from', +1 for each threshold met. For 'Lower = riskier' enter thresholds in descending order. Weights are relative within each factor (0 = not used for that risk).
A4: ID | B4: Risk factor | C4: Indicator | D4: Unit | E4: Data source | F4: Direction | G4: Score 2 from | H4: Score 3 from | I4: Score 4 from | J4: Score 5 from | K4: Weight FC-01 | L4: Weight FC-02 | M4: Weight FC-03 | N4: Weight FC-04 | O4: Weight FC-05 | P4: Weight FC-06 | Q4: Weight FC-07 | R4: Thresholds ordered?
A5: C01 | B5: Customer | C5: % of customers rated high risk (CRR) | D5: % | E5: KYC / CRR system | F5: Higher = riskier | G5: 2 | H5: 5 | I5: 10 | J5: 20 | K5: 3 | L5: 2 | M5: 1 | N5: 1 | O5: 1 | P5: 1 | Q5: 1 | R5: =IF(F5="Higher = riskier",IF(AND(G5<H5,H5<I5,I5<J5),"OK","Check order"),IF(AND(G5>H5,H5>I5,I5>J5),"OK","Check order")) -> OK
A6: C02 | B6: Customer | C6: PEP relationships per 10,000 customers | D6: count | E6: KYC / CRR system | F6: Higher = riskier | G6: 1 | H6: 3 | I6: 6 | J6: 10 | K6: 2 | L6: 1 | M6: 0 | N6: 1 | O6: 3 | P6: 0 | Q6: 1 | R6: =IF(F6="Higher = riskier",IF(AND(G6<H6,H6<I6,I6<J6),"OK","Check order"),IF(AND(G6>H6,H6>I6,I6>J6),"OK","Check order")) -> OK
A7: C03 | B7: Customer | C7: % of customers that are NPOs / charities | D7: % | E7: KYC / CRR system | F7: Higher = riskier | G7: 0.2 | H7: 0.5 | I7: 1 | J7: 2 | K7: 1 | L7: 3 | M7: 0 | N7: 0 | O7: 1 | P7: 0 | Q7: 0 | R7: =IF(F7="Higher = riskier",IF(AND(G7<H7,H7<I7,I7<J7),"OK","Check order"),IF(AND(G7>H7,H7>I7,I7>J7),"OK","Check order")) -> OK
A8: C04 | B8: Customer | C8: % non-resident customers | D8: % | E8: Core banking | F8: Higher = riskier | G8: 5 | H8: 10 | I8: 20 | J8: 35 | K8: 2 | L8: 2 | M8: 1 | N8: 2 | O8: 0 | P8: 1 | Q8: 3 | R8: =IF(F8="Higher = riskier",IF(AND(G8<H8,H8<I8,I8<J8),"OK","Check order"),IF(AND(G8>H8,H8>I8,I8>J8),"OK","Check order")) -> OK
A9: C05 | B9: Customer | C9: % corporate customers with complex or opaque ownership | D9: % | E9: KYC / CRR system | F9: Higher = riskier | G9: 2 | H9: 5 | I9: 10 | J9: 20 | K9: 2 | L9: 1 | M9: 2 | N9: 2 | O9: 1 | P9: 0 | Q9: 3 | R9: =IF(F9="Higher = riskier",IF(AND(G9<H9,H9<I9,I9<J9),"OK","Check order"),IF(AND(G9>H9,H9>I9,I9>J9),"OK","Check order")) -> OK
A10: C06 | B10: Customer | C10: % customers in cash-intensive businesses | D10: % | E10: KYC / CRR system | F10: Higher = riskier | G10: 3 | H10: 7 | I10: 12 | J10: 20 | K10: 2 | L10: 1 | M10: 0 | N10: 0 | O10: 0 | P10: 1 | Q10: 1 | R10: =IF(F10="Higher = riskier",IF(AND(G10<H10,H10<I10,I10<J10),"OK","Check order"),IF(AND(G10>H10,H10>I10,I10>J10),"OK","Check order")) -> OK
A11: C07 | B11: Customer | C11: % customers that are government bodies or SOEs | D11: % | E11: Core banking | F11: Higher = riskier | G11: 1 | H11: 3 | I11: 6 | J11: 10 | K11: 0 | L11: 0 | M11: 0 | N11: 1 | O11: 3 | P11: 0 | Q11: 0 | R11: =IF(F11="Higher = riskier",IF(AND(G11<H11,H11<I11,I11<J11),"OK","Check order"),IF(AND(G11>H11,H11>I11,I11>J11),"OK","Check order")) -> OK
A12: G01 | B12: Geography | C12: % cross-border value with FATF high-risk / increased-monitoring jurisdictions | D12: % | E12: Payments / TM system | F12: Higher = riskier | G12: 0.5 | H12: 2 | I12: 5 | J12: 10 | K12: 3 | L12: 3 | M12: 3 | N12: 2 | O12: 1 | P12: 1 | Q12: 1 | R12: =IF(F12="Higher = riskier",IF(AND(G12<H12,H12<I12,I12<J12),"OK","Check order"),IF(AND(G12>H12,H12>I12,I12>J12),"OK","Check order")) -> OK
A13: G02 | B13: Geography | C13: % payment value involving sanctioned or high sanctions-risk jurisdictions | D13: % | E13: Screening / payments | F13: Higher = riskier | G13: 0.01 | H13: 0.1 | I13: 0.5 | J13: 1 | K13: 1 | L13: 1 | M13: 3 | N13: 3 | O13: 0 | P13: 0 | Q13: 0 | R13: =IF(F13="Higher = riskier",IF(AND(G13<H13,H13<I13,I13<J13),"OK","Check order"),IF(AND(G13>H13,H13>I13,I13>J13),"OK","Check order")) -> OK
A14: G03 | B14: Geography | C14: Host-country national ML/TF risk (NRA-based, 1–5) | D14: score 1–5 | E14: Reference data (HO) | F14: Higher = riskier | G14: 2 | H14: 3 | I14: 4 | J14: 5 | K14: 2 | L14: 2 | M14: 1 | N14: 1 | O14: 1 | P14: 1 | Q14: 1 | R14: =IF(F14="Higher = riskier",IF(AND(G14<H14,H14<I14,I14<J14),"OK","Check order"),IF(AND(G14>H14,H14>I14,I14>J14),"OK","Check order")) -> OK
A15: G04 | B15: Geography | C15: Host-country corruption risk (CPI-based, 1–5) | D15: score 1–5 | E15: Reference data (HO) | F15: Higher = riskier | G15: 2 | H15: 3 | I15: 4 | J15: 5 | K15: 1 | L15: 0 | M15: 0 | N15: 0 | O15: 3 | P15: 1 | Q15: 1 | R15: =IF(F15="Higher = riskier",IF(AND(G15<H15,H15<I15,I15<J15),"OK","Check order"),IF(AND(G15>H15,H15>I15,I15>J15),"OK","Check order")) -> OK
A16: G05 | B16: Geography | C16: % branches in border, free-zone or conflict-affected areas | D16: % | E16: Branch register | F16: Higher = riskier | G16: 2 | H16: 5 | I16: 10 | J16: 20 | K16: 1 | L16: 3 | M16: 1 | N16: 1 | O16: 0 | P16: 1 | Q16: 0 | R16: =IF(F16="Higher = riskier",IF(AND(G16<H16,H16<I16,I16<J16),"OK","Check order"),IF(AND(G16>H16,H16>I16,I16>J16),"OK","Check order")) -> OK
... A35: T07 | B35: Transactions & volumes | C35: FATCA/CRS reportable accounts (% of accounts) | D35: % | E35: Tax reporting system | F35: Higher = riskier | G35: 1 | H35: 3 | I35: 6 | J35: 10 | K35: 0 | L35: 0 | M35: 0 | N35: 0 | O35: 0 | P35: 0 | Q35: 3 | R35: =IF(F35="Higher = riskier",IF(AND(G35<H35,H35<I35,I35<J35),"OK","Check order"),IF(AND(G35>H35,H35>I35,I35>J35),"OK","Check order")) -> OK

Sheet Indicator Data
A1: Raw indicator values by entity (ILLUSTRATIVE SAMPLE DATA)
A2: Replace with values from source systems or Country CO submissions for the assessment period. Leave a cell blank if data is unavailable; Config decides how blanks are treated.
A4: ID | B4: Indicator | C4: Unit | D4: =Entities!A5 -> JO-HO | E4: =Entities!A6 -> JO-IIAB | F4: =Entities!A7 -> JO-INV | G4: =Entities!A8 -> JO-INS | H4: =Entities!A9 -> JO-LSG | I4: =Entities!A10 -> PS | J4: =Entities!A11 -> PS-INV | K4: =Entities!A12 -> LB | L4: =Entities!A13 -> SY | M4: =Entities!A14 -> AE | N4: =Entities!A15 -> BH | O4: =Entities!A16 -> QA | P4: =Entities!A17 -> SA | Q4: =Entities!A18 -> OM | R4: =Entities!A19 -> IQ | S4: =Entities!A20 -> YE | T4: =Entities!A21 -> EG | U4: =Entities!A22 -> DZ | V4: =Entities!A23 -> MA | W4: =Entities!A24 -> TN | X4: =Entities!A25 -> SD | Y4: =Entities!A26 -> GB | Z4: =Entities!A27 -> FR | AA4: =Entities!A28 -> DE | AB4: =Entities!A29 -> IT | AC4: =Entities!A30 -> CH | AD4: =Entities!A31 -> SG | AE4: =Entities!A32 -> CN | AF4: =Entities!A33 -> AU | AG4: =Entities!A34 -> US
A5: =Indicators!A5 -> C01 | B5: =Indicators!C5 -> % of customers rated high risk (CRR) | C5: =Indicators!D5 -> % | D5: 14.91 | E5: 9.26 | F5: 0.16 | G5: 15.49 | H5: 12.22 | I5: 11.18 | J5: 5.71 | K5: 9.01 | L5: 19.46 | M5: 8.24 | N5: 3.76 | O5: 11.46 | P5: 4.75 | Q5: 5.64 | R5: 2.25 | S5: 18.28 | T5: 8.99 | U5: 6.87 | V5: 7.28 | W5: 6.81 | X5: 31.17 | Y5: 3.81 | Z5: 4.57 | AA5: 0.8 | AB5: 14.26 | AC5: 0.13 | AD5: 2.45 | AE5: 2.86 | AF5: 2.66 | AG5: 2.48
A6: =Indicators!A6 -> C02 | B6: =Indicators!C6 -> PEP relationships per 10,000 customers | C6: =Indicators!D6 -> count | D6: 9 | E6: 8 | F6: 2.54 | G6: 9 | H6: 0.93 | I6: 9 | J6: 13 | K6: 8 | L6: 8 | M6: 2.79 | N6: 3.74 | O6: 0.71 | P6: 2.18 | Q6: 4.54 | R6: 7 | S6: 13 | T6: 0.25 | U6: 4.24 | V6: 5 | W6: 5 | X6: 4.19 | Y6: 0.52 | Z6: 0.77 | AA6: 1.53 | AB6: 1.1 | AC6: 1.95 | AD6: 0.73 | AE6: 0.31 | AF6: 0.78 | AG6: 0.11
A7: =Indicators!A7 -> C03 | B7: =Indicators!C7 -> % of customers that are NPOs / charities | C7: =Indicators!D7 -> % | D7: 0.79 | E7: 1.46 | F7: 0 | G7: 0 | H7: 0 | I7: 0.3 | J7: 0 | K7: 0.54 | L7: 2.46 | M7: 1.87 | N7: 1.04 | O7: 0.24 | P7: 1.71 | Q7: 0.62 | R7: 3.01 | S7: 0.83 | T7: 0.64 | U7: 1.6 | V7: 1.41 | W7: 0.71 | X7: 3.18 | Y7: 1.95 | Z7: 0.01 | AA7: 0.19 | AB7: 0.34 | AC7: 0.16 | AD7: 0.26 | AE7: 0.22 | AF7: 0.03 | AG7: 0.12
A8: =Indicators!A8 -> C04 | B8: =Indicators!C8 -> % non-resident customers | C8: =Indicators!D8 -> % | D8: 15.34 | E8: 16.02 | F8: 17.22 | G8: 14.16 | H8: 25.83 | I8: 17.49 | J8: 23.77 | K8: 11.32 | L8: 15.92 | M8: 29.55 | N8: 7.35 | O8: 10.59 | P8: 21.66 | Q8: 21.02 | R8: 31.48 | S8: 27.08 | T8: 6.5 | U8: 31.44 | V8: 10.66 | W8: 7.73 | X8: 38.46 | Y8: 3.52 | Z8: 7.87 | AA8: 5.44 | AB8: 4.76 | AC8: 10.97 | AD8: 7.24 | AE8: 11.14 | AF8: 0.86 | AG8: 6.22
A9: =Indicators!A9 -> C05 | B9: =Indicators!C9 -> % corporate customers with complex or opaque ownership | C9: =Indicators!D9 -> % | D9: 8.51 | E9: 25.48 | F9: 19.18 | G9: 13.23 | H9: 4.27 | I9: 7.95 | J9: 7.85 | K9: 28.87 | L9: 18.73 | M9: 1.07 | N9: 12.44 | O9: 3.93 | P9: 15.97 | Q9: 7.89 | R9: 3.59 | S9: 5.55 | T9: 5.15 | U9: 3.62 | V9: 7.04 | W9: 3.04 | X9: 14.35 | Y9: 7.27 | Z9: 0.93 | AA9: 0.09 | AB9: 5.96 | AC9: 3.22 | AD9: 8.28 | AE9: 1.43 | AF9: 3.51 | AG9: 0.78
A10: =Indicators!A10 -> C06 | B10: =Indicators!C10 -> % customers in cash-intensive businesses | C10: =Indicators!D10 -> % | D10: 5.96 | E10: 2.9 | F10: 3.6 | G10: 3.27 | H10: 19.31 | I10: 11.4 | J10: 30.07 | K10: 13.65 | L10: 12.92 | M10: 8.57 | N10: 10.59 | O10: 19.15 | P10: 7.75 | Q10: 18.88 | R10: 7.17 | S10: 31.59 | T10: 13.62 | U10: 6.34 | V10: 4.35 | W10: 8.67 | X10: 16.36 | Y10: 7.72 | Z10: 3.46 | AA10: 4.3 | AB10: 4.2 | AC10: 0.4 | AD10: 1.75 | AE10: 3.75 | AF10: 10.16 | AG10: 0.13
A11: =Indicators!A11 -> C07 | B11: =Indicators!C11 -> % customers that are government bodies or SOEs | C11: =Indicators!D11 -> % | D11: 3.69 | E11: 4.57 | F11: 1.61 | G11: 1.77 | H11: 1.68 | I11: 7.76 | J11: 5.77 | K11: 9.23 | L11: 4.97 | M11: 9.51 | N11: 5.43 | O11: 3.52 | P11: 3.55 | Q11: 8.73 | R11: 14.16 | S11: 7.89 | T11: 2.47 | U11: 6.11 | V11: 8.29 | W11: 1.49 | X11: 13.82 | Y11: 0.45 | Z11: 5.76 | AA11: 0.79 | AB11: 5 | AC11: 4.68 | AD11: 1.12 | AE11: 2.71 | AF11: 0.88 | AG11: 0.24
A12: =Indicators!A12 -> G01 | B12: =Indicators!C12 -> % cross-border value with FATF high-risk / increased-monitoring jurisdictions | C12: =Indicators!D12 -> % | D12: 1.4 | E12: 0.95 | F12: 0.47 | G12: 2.13 | H12: 3.66 | I12: 15.87 | J12: 7.47 | K12: 4.77 | L12: 7.19 | M12: 3.62 | N12: 3.16 | O12: 3.03 | P12: 9.55 | Q12: 0.97 | R12: 9.04 | S12: 3.49 | T12: 0.2 | U12: 3.79 | V12: 8.8 | W12: 1.18 | X12: 4.27 | Y12: 4.07 | Z12: 0.13 | AA12: 1.25 | AB12: 1.51 | AC12: 1.84 | AD12: 0.49 | AE12: 0.35 | AF12: 1.65 | AG12: 1.29
A13: =Indicators!A13 -> G02 | B13: =Indicators!C13 -> % payment value involving sanctioned or high sanctions-risk jurisdictions | C13: =Indicators!D13 -> % | D13: 0.72 | E13: 0.08 | F13: 0.05 | G13: 1.33 | H13: 0.76 | I13: 1.52 | J13: 0.86 | K13: 0.68 | L13: 0.87 | M13: 0.2 | N13: 0.26 | O13: 0.72 | P13: 0.48 | Q13: 0.93 | R13: 0.09 | S13: 1.21 | T13: 0.58 | U13: 0.28 | V13: 0.41 | W13: 0.34 | X13: 0.88 | Y13: 0 | Z13: 0.03 | AA13: 0.01 | AB13: 0.07 | AC13: 0.01 | AD13: 0.78 | AE13: 0.09 | AF13: 0 | AG13: 0.08
A14: =Indicators!A14 -> G03 | B14: =Indicators!C14 -> Host-country national ML/TF risk (NRA-based, 1–5) | C14: =Indicators!D14 -> score 1–5 | D14: 4 | E14: 2 | F14: 3 | G14: 3 | H14: 4 | I14: 4 | J14: 5 | K14: 5 | L14: 4 | M14: 3 | N14: 3 | O14: 3 | P14: 3 | Q14: 3 | R14: 4 | S14: 5 | T14: 2 | U14: 3 | V14: 4 | W14: 3 | X14: 5 | Y14: 3 | Z14: 2 | AA14: 2 | AB14: 2 | AC14: 3 | AD14: 3 | AE14: 1 | AF14: 2 | AG14: 3
A15: =Indicators!A15 -> G04 | B15: =Indicators!C15 -> Host-country corruption risk (CPI-based, 1–5) | C15: =Indicators!D15 -> score 1–5 | D15: 3 | E15: 3 | F15: 3 | G15: 3 | H15: 4 | I15: 4 | J15: 4 | K15: 4 | L15: 5 | M15: 4 | N15: 4 | O15: 3 | P15: 2 | Q15: 3 | R15: 5 | S15: 4 | T15: 3 | U15: 3 | V15: 3 | W15: 3 | X15: 4 | Y15: 3 | Z15: 3 | AA15: 2 | AB15: 3 | AC15: 2 | AD15: 2 | AE15: 2 | AF15: 2 | AG15: 2
A16: =Indicators!A16 -> G05 | B16: =Indicators!C16 -> % branches in border, free-zone or conflict-affected areas | C16: =Indicators!D16 -> % | D16: 3.97 | E16: 12.83 | F16: 9.6 | G16: 8.41 | H16: 2.62 | I16: 3.13 | J16: 20.14 | K16: 14.88 | L16: 23.74 | M16: 0.93 | N16: 8.17 | O16: 8.08 | P16: 1.55 | Q16: 0.82 | R16: 8.12 | S16: 13.62 | T16: 7.89 | U16: 5.41 | V16: 4.18 | W16: 11.12 | X16: 28.88 | Y16: 2.92 | Z16: 3.99 | AA16: 0.11 | AB16: 0.6 | AC16: 0.51 | AD16: 2.35 | AE16: 9.13 | AF16: 2.5 | AG16: 0.01
... A25: =Indicators!A25 -> D02 | B25: =Indicators!C25 -> % customers introduced via agents or intermediaries | C25: =Indicators!D25 -> % | D25: 13.49 | E25: 4.41 | F25: 2.89 | G25: 9.05 | H25: 28.21 | I25: 5.54 | J25: 4.76 | K25: 27.27 | L25: 6.83 | M25: 5.05 | N25: 26.25 | O25: 8.38 | P25: 2.74 | Q25: 6.28 | R25: 13.38 | S25: 27.29 | T25: 3.29 | U25: 5.48 | V25: 4.52 | W25: 7.48 | X25: 10.89 | Y25: 6.21 | Z25: 3.07 | AA25: 4.08 | AB25: 1.78 | AC25: 6.28 | AD25: 3.15 | AE25: 4.71 | AF25: 0.08 | AG25: 3.54
A26: =Indicators!A26 -> D03 | B26: =Indicators!C26 -> Real-time / digital payments (% of payment value) | C26: =Indicators!D26 -> % | D26: 31 | E26: 11.43 | F26: 5.1 | G26: 16 | H26: 27.63 | I26: 51.64 | J26: 68.37 | K26: 36.53 | L26: 65.56 | M26: 28.12 | N26: 15.55 | O26: 35.75 | P26: 19.89 | Q26: 0.26 | R26: 50.09 | S26: 26.61 | T26: 30.33 | U26: 56.43 | V26: 43.91 | W26: 11.57 | X26: 79.41 | Y26: 34.7 | Z26: 13.12 | AA26: 11.87 | AB26: 12.59 | AC26: 6.7 | AD26: 0.32 | AE26: 12.27 | AF26: 8.13
A27: =Indicators!A27 -> D04 | B27: =Indicators!C27 -> Cash deposit machines and ATMs per branch | C27: =Indicators!D27 -> count | D27: 1.48 | E27: 7 | F27: 0 | G27: 0 | H27: 0 | I27: 6 | J27: 0 | K27: 4.71 | L27: 3.24 | M27: 2.44 | N27: 3.41 | O27: 1.16 | P27: 1.79 | Q27: 2.57 | R27: 3.03 | S27: 3.24 | T27: 1.29 | U27: 4.05 | V27: 3.84 | W27: 1.4 | X27: 7 | Y27: 0.53 | Z27: 0.75 | AA27: 0.79 | AB27: 0.08 | AC27: 1.65 | AD27: 0.84 | AE27: 1.34 | AF27: 1.21 | AG27: 1.88
A28: =Indicators!A28 -> D05 | B28: =Indicators!C28 -> Third parties with public-official contact acting for the bank | C28: =Indicators!D28 -> count | D28: 11 | E28: 7 | F28: 12 | G28: 5 | H28: 0.62 | I28: 28 | J28: 22 | K28: 22 | L28: 6 | M28: 2.21 | N28: 14 | O28: 7 | P28: 8 | Q28: 0.12 | R28: 14 | S28: 14 | T28: 5 | U28: 1.49 | V28: 2.4 | W28: 31 | X28: 26 | Y28: 0.83 | Z28: 0.94 | AA28: 0.94 | AB28: 0.98 | AC28: 4.18 | AD28: 2.57 | AE28: 3.8 | AF28: 0.22 | AG28: 0.11
A29: =Indicators!A29 -> T01 | B29: =Indicators!C29 -> Cash deposits (% of total deposit inflows) | C29: =Indicators!D29 -> % | D29: 2.94 | E29: 9.63 | F29: 18.52 | G29: 12.53 | H29: 9.02 | I29: 28.27 | J29: 13.45 | K29: 27.38 | L29: 52.66 | M29: 7.72 | N29: 15.06 | O29: 26.19 | P29: 6.33 | Q29: 13.54 | R29: 38.75 | S29: 23.6 | T29: 6.43 | U29: 13.33 | V29: 1.53 | W29: 51.68 | X29: 11.32 | Y29: 2.82 | Z29: 8.43 | AA29: 7.97 | AB29: 3.45 | AC29: 8.6 | AD29: 7.54 | AE29: 5.4 | AF29: 1.67 | AG29: 0.13
A30: =Indicators!A30 -> T02 | B30: =Indicators!C30 -> Cross-border wires per month ('000) | C30: =Indicators!D30 -> count ('000) | D30: 34 | E30: 73 | F30: 0 | G30: 0 | H30: 0 | I30: 67 | J30: 0 | K30: 110 | L30: 71 | M30: 13 | N30: 75 | O30: 27 | P30: 21 | Q30: 25 | R30: 114 | S30: 24 | T30: 11 | U30: 45 | V30: 45 | W30: 85 | X30: 109 | Y30: 3.38 | Z30: 16 | AA30: 0.04 | AB30: 16 | AC30: 2.53 | AD30: 10 | AE30: 3.19 | AF30: 1.39 | AG30: 2.45
A31: =Indicators!A31 -> T03 | B31: =Indicators!C31 -> Transactions above USD 1m per month | C31: =Indicators!D31 -> count | D31: 181 | E31: 25 | F31: 110 | G31: 443 | H31: 156 | I31: 421 | J31: 192 | K31: 919 | L31: 684 | M31: 2.12 | N31: 270 | O31: 95 | P31: 279 | Q31: 179 | R31: 165 | S31: 482 | T31: 454 | U31: 329 | V31: 217 | W31: 175 | X31: 176 | Y31: 25 | Z31: 46 | AA31: 64 | AB31: 55 | AC31: 133 | AD31: 33 | AE31: 84 | AF31: 0.21
A32: =Indicators!A32 -> T04 | B32: =Indicators!C32 -> TM alerts per 1,000 customers per month | C32: =Indicators!D32 -> count | D32: 4.69 | E32: 5 | F32: 4.23 | G32: 7 | H32: 5 | I32: 23 | J32: 9 | K32: 3.87 | L32: 32 | M32: 6 | N32: 3.42 | O32: 10 | P32: 8 | Q32: 10 | R32: 13 | S32: 21 | T32: 9 | U32: 14 | V32: 24 | W32: 15 | X32: 16 | Y32: 0.4 | Z32: 0.17 | AA32: 10 | AB32: 0.04 | AC32: 8 | AD32: 2.62 | AE32: 6 | AF32: 7 | AG32: 9
A33: =Indicators!A33 -> T05 | B33: =Indicators!C33 -> STRs filed per 10,000 customers per year | C33: =Indicators!D33 -> count | D33: 1.05 | E33: 9 | F33: 3.07 | G33: 1.63 | H33: 4.19 | I33: 14 | J33: 8 | K33: 6 | L33: 7 | M33: 9 | N33: 0.32 | O33: 4.22 | P33: 2.12 | Q33: 4.15 | R33: 6 | S33: 9 | T33: 4.91 | U33: 6 | V33: 2.24 | W33: 10 | X33: 9 | Y33: 0.92 | Z33: 1.15 | AA33: 1.08 | AB33: 0.71 | AC33: 2.9 | AD33: 0.57 | AE33: 0.56 | AF33: 0.22 | AG33: 1.32
A34: =Indicators!A34 -> T06 | B34: =Indicators!C34 -> Fraud cases per 10,000 customers per year | C34: =Indicators!D34 -> count | D34: 3.65 | E34: 1.03 | F34: 1.59 | G34: 2.55 | H34: 8 | I34: 16 | J34: 7 | K34: 7 | L34: 8 | M34: 15 | N34: 2.93 | O34: 0.69 | P34: 8 | Q34: 3.76 | R34: 7 | S34: 7 | T34: 6 | U34: 8 | V34: 14 | W34: 6 | X34: 10 | Y34: 0.78 | Z34: 1.34 | AA34: 0.02 | AB34: 2.13 | AC34: 5 | AD34: 2.17 | AE34: 1.42 | AF34: 1.39 | AG34: 6
A35: =Indicators!A35 -> T07 | B35: =Indicators!C35 -> FATCA/CRS reportable accounts (% of accounts) | C35: =Indicators!D35 -> % | D35: 5.03 | E35: 3 | F35: 3.94 | G35: 5.29 | H35: 1.03 | I35: 6.97 | J35: 14.88 | K35: 10.93 | L35: 8.72 | M35: 4.89 | N35: 2.05 | O35: 9.68 | P35: 5.59 | Q35: 5.31 | R35: 9.57 | S35: 7.04 | T35: 0.34 | U35: 9.77 | V35: 1.9 | W35: 2.08 | X35: 2.15 | Y35: 0.53 | Z35: 0.3 | AA35: 1.1 | AB35: 0.83 | AC35: 1.26 | AD35: 0.12 | AE35: 0.5 | AF35: 0.66 | AG35: 2.22

Sheet Indicator Scores
A1: Indicator scores (1–5) by entity
A2: Formula sheet – do not edit. A '-' means no data and the indicator is excluded (when Config = Exclude and reweight).
A4: ID | B4: Indicator | C4: Unit | D4: =Entities!A5 -> JO-HO | E4: =Entities!A6 -> JO-IIAB | F4: =Entities!A7 -> JO-INV | G4: =Entities!A8 -> JO-INS | H4: =Entities!A9 -> JO-LSG | I4: =Entities!A10 -> PS | J4: =Entities!A11 -> PS-INV | K4: =Entities!A12 -> LB | L4: =Entities!A13 -> SY | M4: =Entities!A14 -> AE | N4: =Entities!A15 -> BH | O4: =Entities!A16 -> QA | P4: =Entities!A17 -> SA | Q4: =Entities!A18 -> OM | R4: =Entities!A19 -> IQ | S4: =Entities!A20 -> YE | T4: =Entities!A21 -> EG | U4: =Entities!A22 -> DZ | V4: =Entities!A23 -> MA | W4: =Entities!A24 -> TN | X4: =Entities!A25 -> SD | Y4: =Entities!A26 -> GB | Z4: =Entities!A27 -> FR | AA4: =Entities!A28 -> DE | AB4: =Entities!A29 -> IT | AC4: =Entities!A30 -> CH | AD4: =Entities!A31 -> SG | AE4: =Entities!A32 -> CN | AF4: =Entities!A33 -> AU | AG4: =Entities!A34 -> US
A5: =Indicators!A5 -> C01 | B5: =Indicators!C5 -> % of customers rated high risk (CRR) | C5: =Indicators!D5 -> % | D5: =IF('Indicator Data'!D5="",IF(Config!$C$15="Score as High (5)",5,0),IF(Indicators!$F5="Higher = riskier",1+('Indicator Data'!D5>=Indicators!$G5)+('Indicator Data'!D5>=Indicators!$H5)+('Indicator Data'!D5>=Indicators!$I5)+('Indicator Data'!D5>=Indicators!$J5),1+('Indicator Data'!D5<=Indicators!$G5)+('Indicator Data'!D5<=Indicators!$H5)+('Indicator Data'!D5<=Indicators!$I5)+('Indicator Data'!D5<=Indicators!$J5))) -> 4 | E5: =IF('Indicator Data'!E5="",IF(Config!$C$15="Score as High (5)",5,0),IF(Indicators!$F5="Higher = riskier",1+('Indicator Data'!E5>=Indicators!$G5)+('Indicator Data'!E5>=Indicators!$H5)+('Indicator Data'!E5>=Indicators!$I5)+('Indicator Data'!E5>=Indicators!$J5),1+('Indicator Data'!E5<=Indicators!$G5)+('Indicator Data'!E5<=Indicators!$H5)+('Indicator Data'!E5<=Indicators!$I5)+('Indicator Data'!E5<=Indicators!$J5))) -> 3 | F5: =IF('Indicator Data'!F5="",IF(Config!$C$15="Score as High (5)",5,0),IF(Indicators!$F5="Higher = riskier",1+('Indicator Data'!F5>=Indicators!$G5)+('Indicator Data'!F5>=Indicators!$H5)+('Indicator Data'!F5>=Indicators!$I5)+('Indicator Data'!F5>=Indicators!$J5),1+('Indicator Data'!F5<=Indicators!$G5)+('Indicator Data'!F5<=Indicators!$H5)+('Indicator Data'!F5<=Indicators!$I5)+('Indicator Data'!F5<=Indicators!$J5))) -> 1 | G5: =IF('Indicator Data'!G5="",IF(Config!$C$15="Score as High (5)",5,0),IF(Indicators!$F5="Higher = riskier",1+('Indicator Data'!G5>=Indicators!$G5)+('Indicator Data'!G5>=Indicators!$H5)+('Indicator Data'!G5>=Indicators!$I5)+('Indicator Data'!G5>=Indicators!$J5),1+('Indicator Data'!G5<=Indicators!$G5)+('Indicator Data'!G5<=Indicators!$H5)+('Indicator Data'!G5<=Indicators!$I5)+('Indicator Data'!G5<=Indicators!$J5))) -> 4 | H5: =IF('Indicator Data'!H5="",IF(Config!$C$15="Score as High (5)",5,0),IF(Indicators!$F5="Higher = riskier",1+('Indicator Data'!H5>=Indicators!$G5)+('Indicator Data'!H5>=Indicators!$H5)+('Indicator Data'!H5>=Indicators!$I5)+('Indicator Data'!H5>=Indicators!$J5),1+('Indicator Data'!H5<=Indicators!$G5)+('Indicator Data'!H5<=Indicators!$H5)+('Indicator Data'!H5<=Indicators!$I5)+('Indicator Data'!H5<=Indicators!$J5))) -> 4 | I5: =IF('Indicator Data'!I5="",IF(Config!$C$15="Score as High (5)",5,0),IF(Indicators!$F5="Higher = riskier",1+('Indicator Data'!I5>=Indicators!$G5)+('Indicator Data'!I5>=Indicators!$H5)+('Indicator Data'!I5>=Indicators!$I5)+('Indicator Data'!I5>=Indicators!$J5),1+('Indicator Data'!I5<=Indicators!$G5)+('Indicator Data'!I5<=Indicators!$H5)+('Indicator Data'!I5<=Indicators!$I5)+('Indicator Data'!I5<=Indicators!$J5))) -> 4 | J5: =IF('Indicator Data'!J5="",IF(Config!$C$15="Score as High (5)",5,0),IF(Indicators!$F5="Higher = riskier",1+('Indicator Data'!J5>=Indicators!$G5)+('Indicator Data'!J5>=Indicators!$H5)+('Indicator Data'!J5>=Indicators!$I5)+('Indicator Data'!J5>=Indicators!$J5),1+('Indicator Data'!J5<=Indicators!$G5)+('Indicator Data'!J5<=Indicators!$H5)+('Indicator Data'!J5<=Indicators!$I5)+('Indicator Data'!J5<=Indicators!$J5))) -> 3 | K5: =IF('Indicator Data'!K5="",IF(Config!$C$15="Score as High (5)",5,0),IF(Indicators!$F5="Higher = riskier",1+('Indicator Data'!K5>=Indicators!$G5)+('Indicator Data'!K5>=Indicators!$H5)+('Indicator Data'!K5>=Indicators!$I5)+('Indicator Data'!K5>=Indicators!$J5),1+('Indicator Data'!K5<=Indicators!$G5)+('Indicator Data'!K5<=Indicators!$H5)+('Indicator Data'!K5<=Indicators!$I5)+('Indicator Data'!K5<=Indicators!$J5))) -> 3 | ... AG5: =IF('Indicator Data'!AG5="",IF(Config!$C$15="Score as High (5)",5,0),IF(Indicators!$F5="Higher = riskier",1+('Indicator Data'!AG5>=Indicators!$G5)+('Indicator Data'!AG5>=Indicators!$H5)+('Indicator Data'!AG5>=Indicators!$I5)+('Indicator Data'!AG5>=Indicators!$J5),1+('Indicator Data'!AG5<=Indicators!$G5)+('Indicator Data'!AG5<=Indicators!$H5)+('Indicator Data'!AG5<=Indicators!$I5)+('Indicator Data'!AG5<=Indicators!$J5))) -> 2
A6: =Indicators!A6 -> C02 | B6: =Indicators!C6 -> PEP relationships per 10,000 customers | C6: =Indicators!D6 -> count | D6: =IF('Indicator Data'!D6="",IF(Config!$C$15="Score as High (5)",5,0),IF(Indicators!$F6="Higher = riskier",1+('Indicator Data'!D6>=Indicators!$G6)+('Indicator Data'!D6>=Indicators!$H6)+('Indicator Data'!D6>=Indicators!$I6)+('Indicator Data'!D6>=Indicators!$J6),1+('Indicator Data'!D6<=Indicators!$G6)+('Indicator Data'!D6<=Indicators!$H6)+('Indicator Data'!D6<=Indicators!$I6)+('Indicator Data'!D6<=Indicators!$J6))) -> 4 | E6: =IF('Indicator Data'!E6="",IF(Config!$C$15="Score as High (5)",5,0),IF(Indicators!$F6="Higher = riskier",1+('Indicator Data'!E6>=Indicators!$G6)+('Indicator Data'!E6>=Indicators!$H6)+('Indicator Data'!E6>=Indicators!$I6)+('Indicator Data'!E6>=Indicators!$J6),1+('Indicator Data'!E6<=Indicators!$G6)+('Indicator Data'!E6<=Indicators!$H6)+('Indicator Data'!E6<=Indicators!$I6)+('Indicator Data'!E6<=Indicators!$J6))) -> 4 | F6: =IF('Indicator Data'!F6="",IF(Config!$C$15="Score as High (5)",5,0),IF(Indicators!$F6="Higher = riskier",1+('Indicator Data'!F6>=Indicators!$G6)+('Indicator Data'!F6>=Indicators!$H6)+('Indicator Data'!F6>=Indicators!$I6)+('Indicator Data'!F6>=Indicators!$J6),1+('Indicator Data'!F6<=Indicators!$G6)+('Indicator Data'!F6<=Indicators!$H6)+('Indicator Data'!F6<=Indicators!$I6)+('Indicator Data'!F6<=Indicators!$J6))) -> 2 | G6: =IF('Indicator Data'!G6="",IF(Config!$C$15="Score as High (5)",5,0),IF(Indicators!$F6="Higher = riskier",1+('Indicator Data'!G6>=Indicators!$G6)+('Indicator Data'!G6>=Indicators!$H6)+('Indicator Data'!G6>=Indicators!$I6)+('Indicator Data'!G6>=Indicators!$J6),1+('Indicator Data'!G6<=Indicators!$G6)+('Indicator Data'!G6<=Indicators!$H6)+('Indicator Data'!G6<=Indicators!$I6)+('Indicator Data'!G6<=Indicators!$J6))) -> 4 | H6: =IF('Indicator Data'!H6="",IF(Config!$C$15="Score as High (5)",5,0),IF(Indicators!$F6="Higher = riskier",1+('Indicator Data'!H6>=Indicators!$G6)+('Indicator Data'!H6>=Indicators!$H6)+('Indicator Data'!H6>=Indicators!$I6)+('Indicator Data'!H6>=Indicators!$J6),1+('Indicator Data'!H6<=Indicators!$G6)+('Indicator Data'!H6<=Indicators!$H6)+('Indicator Data'!H6<=Indicators!$I6)+('Indicator Data'!H6<=Indicators!$J6))) -> 1 | I6: =IF('Indicator Data'!I6="",IF(Config!$C$15="Score as High (5)",5,0),IF(Indicators!$F6="Higher = riskier",1+('Indicator Data'!I6>=Indicators!$G6)+('Indicator Data'!I6>=Indicators!$H6)+('Indicator Data'!I6>=Indicators!$I6)+('Indicator Data'!I6>=Indicators!$J6),1+('Indicator Data'!I6<=Indicators!$G6)+('Indicator Data'!I6<=Indicators!$H6)+('Indicator Data'!I6<=Indicators!$I6)+('Indicator Data'!I6<=Indicators!$J6))) -> 4 | J6: =IF('Indicator Data'!J6="",IF(Config!$C$15="Score as High (5)",5,0),IF(Indicators!$F6="Higher = riskier",1+('Indicator Data'!J6>=Indicators!$G6)+('Indicator Data'!J6>=Indicators!$H6)+('Indicator Data'!J6>=Indicators!$I6)+('Indicator Data'!J6>=Indicators!$J6),1+('Indicator Data'!J6<=Indicators!$G6)+('Indicator Data'!J6<=Indicators!$H6)+('Indicator Data'!J6<=Indicators!$I6)+('Indicator Data'!J6<=Indicators!$J6))) -> 5 | K6: =IF('Indicator Data'!K6="",IF(Config!$C$15="Score as High (5)",5,0),IF(Indicators!$F6="Higher = riskier",1+('Indicator Data'!K6>=Indicators!$G6)+('Indicator Data'!K6>=Indicators!$H6)+('Indicator Data'!K6>=Indicators!$I6)+('Indicator Data'!K6>=Indicators!$J6),1+('Indicator Data'!K6<=Indicators!$G6)+('Indicator Data'!K6<=Indicators!$H6)+('Indicator Data'!K6<=Indicators!$I6)+('Indicator Data'!K6<=Indicators!$J6))) -> 4 | ... AG6: =IF('Indicator Data'!AG6="",IF(Config!$C$15="Score as High (5)",5,0),IF(Indicators!$F6="Higher = riskier",1+('Indicator Data'!AG6>=Indicators!$G6)+('Indicator Data'!AG6>=Indicators!$H6)+('Indicator Data'!AG6>=Indicators!$I6)+('Indicator Data'!AG6>=Indicators!$J6),1+('Indicator Data'!AG6<=Indicators!$G6)+('Indicator Data'!AG6<=Indicators!$H6)+('Indicator Data'!AG6<=Indicators!$I6)+('Indicator Data'!AG6<=Indicators!$J6))) -> 1
A7: =Indicators!A7 -> C03 | B7: =Indicators!C7 -> % of customers that are NPOs / charities | C7: =Indicators!D7 -> % | D7: =IF('Indicator Data'!D7="",IF(Config!$C$15="Score as High (5)",5,0),IF(Indicators!$F7="Higher = riskier",1+('Indicator Data'!D7>=Indicators!$G7)+('Indicator Data'!D7>=Indicators!$H7)+('Indicator Data'!D7>=Indicators!$I7)+('Indicator Data'!D7>=Indicators!$J7),1+('Indicator Data'!D7<=Indicators!$G7)+('Indicator Data'!D7<=Indicators!$H7)+('Indicator Data'!D7<=Indicators!$I7)+('Indicator Data'!D7<=Indicators!$J7))) -> 3 | E7: =IF('Indicator Data'!E7="",IF(Config!$C$15="Score as High (5)",5,0),IF(Indicators!$F7="Higher = riskier",1+('Indicator Data'!E7>=Indicators!$G7)+('Indicator Data'!E7>=Indicators!$H7)+('Indicator Data'!E7>=Indicators!$I7)+('Indicator Data'!E7>=Indicators!$J7),1+('Indicator Data'!E7<=Indicators!$G7)+('Indicator Data'!E7<=Indicators!$H7)+('Indicator Data'!E7<=Indicators!$I7)+('Indicator Data'!E7<=Indicators!$J7))) -> 4 | F7: =IF('Indicator Data'!F7="",IF(Config!$C$15="Score as High (5)",5,0),IF(Indicators!$F7="Higher = riskier",1+('Indicator Data'!F7>=Indicators!$G7)+('Indicator Data'!F7>=Indicators!$H7)+('Indicator Data'!F7>=Indicators!$I7)+('Indicator Data'!F7>=Indicators!$J7),1+('Indicator Data'!F7<=Indicators!$G7)+('Indicator Data'!F7<=Indicators!$H7)+('Indicator Data'!F7<=Indicators!$I7)+('Indicator Data'!F7<=Indicators!$J7))) -> 1 | G7: =IF('Indicator Data'!G7="",IF(Config!$C$15="Score as High (5)",5,0),IF(Indicators!$F7="Higher = riskier",1+('Indicator Data'!G7>=Indicators!$G7)+('Indicator Data'!G7>=Indicators!$H7)+('Indicator Data'!G7>=Indicators!$I7)+('Indicator Data'!G7>=Indicators!$J7),1+('Indicator Data'!G7<=Indicators!$G7)+('Indicator Data'!G7<=Indicators!$H7)+('Indicator Data'!G7<=Indicators!$I7)+('Indicator Data'!G7<=Indicators!$J7))) -> 1 | H7: =IF('Indicator Data'!H7="",IF(Config!$C$15="Score as High (5)",5,0),IF(Indicators!$F7="Higher = riskier",1+('Indicator Data'!H7>=Indicators!$G7)+('Indicator Data'!H7>=Indicators!$H7)+('Indicator Data'!H7>=Indicators!$I7)+('Indicator Data'!H7>=Indicators!$J7),1+('Indicator Data'!H7<=Indicators!$G7)+('Indicator Data'!H7<=Indicators!$H7)+('Indicator Data'!H7<=Indicators!$I7)+('Indicator Data'!H7<=Indicators!$J7))) -> 1 | I7: =IF('Indicator Data'!I7="",IF(Config!$C$15="Score as High (5)",5,0),IF(Indicators!$F7="Higher = riskier",1+('Indicator Data'!I7>=Indicators!$G7)+('Indicator Data'!I7>=Indicators!$H7)+('Indicator Data'!I7>=Indicators!$I7)+('Indicator Data'!I7>=Indicators!$J7),1+('Indicator Data'!I7<=Indicators!$G7)+('Indicator Data'!I7<=Indicators!$H7)+('Indicator Data'!I7<=Indicators!$I7)+('Indicator Data'!I7<=Indicators!$J7))) -> 2 | J7: =IF('Indicator Data'!J7="",IF(Config!$C$15="Score as High (5)",5,0),IF(Indicators!$F7="Higher = riskier",1+('Indicator Data'!J7>=Indicators!$G7)+('Indicator Data'!J7>=Indicators!$H7)+('Indicator Data'!J7>=Indicators!$I7)+('Indicator Data'!J7>=Indicators!$J7),1+('Indicator Data'!J7<=Indicators!$G7)+('Indicator Data'!J7<=Indicators!$H7)+('Indicator Data'!J7<=Indicators!$I7)+('Indicator Data'!J7<=Indicators!$J7))) -> 1 | K7: =IF('Indicator Data'!K7="",IF(Config!$C$15="Score as High (5)",5,0),IF(Indicators!$F7="Higher = riskier",1+('Indicator Data'!K7>=Indicators!$G7)+('Indicator Data'!K7>=Indicators!$H7)+('Indicator Data'!K7>=Indicators!$I7)+('Indicator Data'!K7>=Indicators!$J7),1+('Indicator Data'!K7<=Indicators!$G7)+('Indicator Data'!K7<=Indicators!$H7)+('Indicator Data'!K7<=Indicators!$I7)+('Indicator Data'!K7<=Indicators!$J7))) -> 3 | ... AG7: =IF('Indicator Data'!AG7="",IF(Config!$C$15="Score as High (5)",5,0),IF(Indicators!$F7="Higher = riskier",1+('Indicator Data'!AG7>=Indicators!$G7)+('Indicator Data'!AG7>=Indicators!$H7)+('Indicator Data'!AG7>=Indicators!$I7)+('Indicator Data'!AG7>=Indicators!$J7),1+('Indicator Data'!AG7<=Indicators!$G7)+('Indicator Data'!AG7<=Indicators!$H7)+('Indicator Data'!AG7<=Indicators!$I7)+('Indicator Data'!AG7<=Indicators!$J7))) -> 1
A8: =Indicators!A8 -> C04 | B8: =Indicators!C8 -> % non-resident customers | C8: =Indicators!D8 -> % | D8: =IF('Indicator Data'!D8="",IF(Config!$C$15="Score as High (5)",5,0),IF(Indicators!$F8="Higher = riskier",1+('Indicator Data'!D8>=Indicators!$G8)+('Indicator Data'!D8>=Indicators!$H8)+('Indicator Data'!D8>=Indicators!$I8)+('Indicator Data'!D8>=Indicators!$J8),1+('Indicator Data'!D8<=Indicators!$G8)+('Indicator Data'!D8<=Indicators!$H8)+('Indicator Data'!D8<=Indicators!$I8)+('Indicator Data'!D8<=Indicators!$J8))) -> 3 | E8: =IF('Indicator Data'!E8="",IF(Config!$C$15="Score as High (5)",5,0),IF(Indicators!$F8="Higher = riskier",1+('Indicator Data'!E8>=Indicators!$G8)+('Indicator Data'!E8>=Indicators!$H8)+('Indicator Data'!E8>=Indicators!$I8)+('Indicator Data'!E8>=Indicators!$J8),1+('Indicator Data'!E8<=Indicators!$G8)+('Indicator Data'!E8<=Indicators!$H8)+('Indicator Data'!E8<=Indicators!$I8)+('Indicator Data'!E8<=Indicators!$J8))) -> 3 | F8: =IF('Indicator Data'!F8="",IF(Config!$C$15="Score as High (5)",5,0),IF(Indicators!$F8="Higher = riskier",1+('Indicator Data'!F8>=Indicators!$G8)+('Indicator Data'!F8>=Indicators!$H8)+('Indicator Data'!F8>=Indicators!$I8)+('Indicator Data'!F8>=Indicators!$J8),1+('Indicator Data'!F8<=Indicators!$G8)+('Indicator Data'!F8<=Indicators!$H8)+('Indicator Data'!F8<=Indicators!$I8)+('Indicator Data'!F8<=Indicators!$J8))) -> 3 | G8: =IF('Indicator Data'!G8="",IF(Config!$C$15="Score as High (5)",5,0),IF(Indicators!$F8="Higher = riskier",1+('Indicator Data'!G8>=Indicators!$G8)+('Indicator Data'!G8>=Indicators!$H8)+('Indicator Data'!G8>=Indicators!$I8)+('Indicator Data'!G8>=Indicators!$J8),1+('Indicator Data'!G8<=Indicators!$G8)+('Indicator Data'!G8<=Indicators!$H8)+('Indicator Data'!G8<=Indicators!$I8)+('Indicator Data'!G8<=Indicators!$J8))) -> 3 | H8: =IF('Indicator Data'!H8="",IF(Config!$C$15="Score as High (5)",5,0),IF(Indicators!$F8="Higher = riskier",1+('Indicator Data'!H8>=Indicators!$G8)+('Indicator Data'!H8>=Indicators!$H8)+('Indicator Data'!H8>=Indicators!$I8)+('Indicator Data'!H8>=Indicators!$J8),1+('Indicator Data'!H8<=Indicators!$G8)+('Indicator Data'!H8<=Indicators!$H8)+('Indicator Data'!H8<=Indicators!$I8)+('Indicator Data'!H8<=Indicators!$J8))) -> 4 | I8: =IF('Indicator Data'!I8="",IF(Config!$C$15="Score as High (5)",5,0),IF(Indicators!$F8="Higher = riskier",1+('Indicator Data'!I8>=Indicators!$G8)+('Indicator Data'!I8>=Indicators!$H8)+('Indicator Data'!I8>=Indicators!$I8)+('Indicator Data'!I8>=Indicators!$J8),1+('Indicator Data'!I8<=Indicators!$G8)+('Indicator Data'!I8<=Indicators!$H8)+('Indicator Data'!I8<=Indicators!$I8)+('Indicator Data'!I8<=Indicators!$J8))) -> 3 | J8: =IF('Indicator Data'!J8="",IF(Config!$C$15="Score as High (5)",5,0),IF(Indicators!$F8="Higher = riskier",1+('Indicator Data'!J8>=Indicators!$G8)+('Indicator Data'!J8>=Indicators!$H8)+('Indicator Data'!J8>=Indicators!$I8)+('Indicator Data'!J8>=Indicators!$J8),1+('Indicator Data'!J8<=Indicators!$G8)+('Indicator Data'!J8<=Indicators!$H8)+('Indicator Data'!J8<=Indicators!$I8)+('Indicator Data'!J8<=Indicators!$J8))) -> 4 | K8: =IF('Indicator Data'!K8="",IF(Config!$C$15="Score as High (5)",5,0),IF(Indicators!$F8="Higher = riskier",1+('Indicator Data'!K8>=Indicators!$G8)+('Indicator Data'!K8>=Indicators!$H8)+('Indicator Data'!K8>=Indicators!$I8)+('Indicator Data'!K8>=Indicators!$J8),1+('Indicator Data'!K8<=Indicators!$G8)+('Indicator Data'!K8<=Indicators!$H8)+('Indicator Data'!K8<=Indicators!$I8)+('Indicator Data'!K8<=Indicators!$J8))) -> 3 | ... AG8: =IF('Indicator Data'!AG8="",IF(Config!$C$15="Score as High (5)",5,0),IF(Indicators!$F8="Higher = riskier",1+('Indicator Data'!AG8>=Indicators!$G8)+('Indicator Data'!AG8>=Indicators!$H8)+('Indicator Data'!AG8>=Indicators!$I8)+('Indicator Data'!AG8>=Indicators!$J8),1+('Indicator Data'!AG8<=Indicators!$G8)+('Indicator Data'!AG8<=Indicators!$H8)+('Indicator Data'!AG8<=Indicators!$I8)+('Indicator Data'!AG8<=Indicators!$J8))) -> 2
A9: =Indicators!A9 -> C05 | B9: =Indicators!C9 -> % corporate customers with complex or opaque ownership | C9: =Indicators!D9 -> % | D9: =IF('Indicator Data'!D9="",IF(Config!$C$15="Score as High (5)",5,0),IF(Indicators!$F9="Higher = riskier",1+('Indicator Data'!D9>=Indicators!$G9)+('Indicator Data'!D9>=Indicators!$H9)+('Indicator Data'!D9>=Indicators!$I9)+('Indicator Data'!D9>=Indicators!$J9),1+('Indicator Data'!D9<=Indicators!$G9)+('Indicator Data'!D9<=Indicators!$H9)+('Indicator Data'!D9<=Indicators!$I9)+('Indicator Data'!D9<=Indicators!$J9))) -> 3 | E9: =IF('Indicator Data'!E9="",IF(Config!$C$15="Score as High (5)",5,0),IF(Indicators!$F9="Higher = riskier",1+('Indicator Data'!E9>=Indicators!$G9)+('Indicator Data'!E9>=Indicators!$H9)+('Indicator Data'!E9>=Indicators!$I9)+('Indicator Data'!E9>=Indicators!$J9),1+('Indicator Data'!E9<=Indicators!$G9)+('Indicator Data'!E9<=Indicators!$H9)+('Indicator Data'!E9<=Indicators!$I9)+('Indicator Data'!E9<=Indicators!$J9))) -> 5 | F9: =IF('Indicator Data'!F9="",IF(Config!$C$15="Score as High (5)",5,0),IF(Indicators!$F9="Higher = riskier",1+('Indicator Data'!F9>=Indicators!$G9)+('Indicator Data'!F9>=Indicators!$H9)+('Indicator Data'!F9>=Indicators!$I9)+('Indicator Data'!F9>=Indicators!$J9),1+('Indicator Data'!F9<=Indicators!$G9)+('Indicator Data'!F9<=Indicators!$H9)+('Indicator Data'!F9<=Indicators!$I9)+('Indicator Data'!F9<=Indicators!$J9))) -> 4 | G9: =IF('Indicator Data'!G9="",IF(Config!$C$15="Score as High (5)",5,0),IF(Indicators!$F9="Higher = riskier",1+('Indicator Data'!G9>=Indicators!$G9)+('Indicator Data'!G9>=Indicators!$H9)+('Indicator Data'!G9>=Indicators!$I9)+('Indicator Data'!G9>=Indicators!$J9),1+('Indicator Data'!G9<=Indicators!$G9)+('Indicator Data'!G9<=Indicators!$H9)+('Indicator Data'!G9<=Indicators!$I9)+('Indicator Data'!G9<=Indicators!$J9))) -> 4 | H9: =IF('Indicator Data'!H9="",IF(Config!$C$15="Score as High (5)",5,0),IF(Indicators!$F9="Higher = riskier",1+('Indicator Data'!H9>=Indicators!$G9)+('Indicator Data'!H9>=Indicators!$H9)+('Indicator Data'!H9>=Indicators!$I9)+('Indicator Data'!H9>=Indicators!$J9),1+('Indicator Data'!H9<=Indicators!$G9)+('Indicator Data'!H9<=Indicators!$H9)+('Indicator Data'!H9<=Indicators!$I9)+('Indicator Data'!H9<=Indicators!$J9))) -> 2 | I9: =IF('Indicator Data'!I9="",IF(Config!$C$15="Score as High (5)",5,0),IF(Indicators!$F9="Higher = riskier",1+('Indicator Data'!I9>=Indicators!$G9)+('Indicator Data'!I9>=Indicators!$H9)+('Indicator Data'!I9>=Indicators!$I9)+('Indicator Data'!I9>=Indicators!$J9),1+('Indicator Data'!I9<=Indicators!$G9)+('Indicator Data'!I9<=Indicators!$H9)+('Indicator Data'!I9<=Indicators!$I9)+('Indicator Data'!I9<=Indicators!$J9))) -> 3 | J9: =IF('Indicator Data'!J9="",IF(Config!$C$15="Score as High (5)",5,0),IF(Indicators!$F9="Higher = riskier",1+('Indicator Data'!J9>=Indicators!$G9)+('Indicator Data'!J9>=Indicators!$H9)+('Indicator Data'!J9>=Indicators!$I9)+('Indicator Data'!J9>=Indicators!$J9),1+('Indicator Data'!J9<=Indicators!$G9)+('Indicator Data'!J9<=Indicators!$H9)+('Indicator Data'!J9<=Indicators!$I9)+('Indicator Data'!J9<=Indicators!$J9))) -> 3 | K9: =IF('Indicator Data'!K9="",IF(Config!$C$15="Score as High (5)",5,0),IF(Indicators!$F9="Higher = riskier",1+('Indicator Data'!K9>=Indicators!$G9)+('Indicator Data'!K9>=Indicators!$H9)+('Indicator Data'!K9>=Indicators!$I9)+('Indicator Data'!K9>=Indicators!$J9),1+('Indicator Data'!K9<=Indicators!$G9)+('Indicator Data'!K9<=Indicators!$H9)+('Indicator Data'!K9<=Indicators!$I9)+('Indicator Data'!K9<=Indicators!$J9))) -> 5 | ... AG9: =IF('Indicator Data'!AG9="",IF(Config!$C$15="Score as High (5)",5,0),IF(Indicators!$F9="Higher = riskier",1+('Indicator Data'!AG9>=Indicators!$G9)+('Indicator Data'!AG9>=Indicators!$H9)+('Indicator Data'!AG9>=Indicators!$I9)+('Indicator Data'!AG9>=Indicators!$J9),1+('Indicator Data'!AG9<=Indicators!$G9)+('Indicator Data'!AG9<=Indicators!$H9)+('Indicator Data'!AG9<=Indicators!$I9)+('Indicator Data'!AG9<=Indicators!$J9))) -> 1
A10: =Indicators!A10 -> C06 | B10: =Indicators!C10 -> % customers in cash-intensive businesses | C10: =Indicators!D10 -> % | D10: =IF('Indicator Data'!D10="",IF(Config!$C$15="Score as High (5)",5,0),IF(Indicators!$F10="Higher = riskier",1+('Indicator Data'!D10>=Indicators!$G10)+('Indicator Data'!D10>=Indicators!$H10)+('Indicator Data'!D10>=Indicators!$I10)+('Indicator Data'!D10>=Indicators!$J10),1+('Indicator Data'!D10<=Indicators!$G10)+('Indicator Data'!D10<=Indicators!$H10)+('Indicator Data'!D10<=Indicators!$I10)+('Indicator Data'!D10<=Indicators!$J10))) -> 2 | E10: =IF('Indicator Data'!E10="",IF(Config!$C$15="Score as High (5)",5,0),IF(Indicators!$F10="Higher = riskier",1+('Indicator Data'!E10>=Indicators!$G10)+('Indicator Data'!E10>=Indicators!$H10)+('Indicator Data'!E10>=Indicators!$I10)+('Indicator Data'!E10>=Indicators!$J10),1+('Indicator Data'!E10<=Indicators!$G10)+('Indicator Data'!E10<=Indicators!$H10)+('Indicator Data'!E10<=Indicators!$I10)+('Indicator Data'!E10<=Indicators!$J10))) -> 1 | F10: =IF('Indicator Data'!F10="",IF(Config!$C$15="Score as High (5)",5,0),IF(Indicators!$F10="Higher = riskier",1+('Indicator Data'!F10>=Indicators!$G10)+('Indicator Data'!F10>=Indicators!$H10)+('Indicator Data'!F10>=Indicators!$I10)+('Indicator Data'!F10>=Indicators!$J10),1+('Indicator Data'!F10<=Indicators!$G10)+('Indicator Data'!F10<=Indicators!$H10)+('Indicator Data'!F10<=Indicators!$I10)+('Indicator Data'!F10<=Indicators!$J10))) -> 2 | G10: =IF('Indicator Data'!G10="",IF(Config!$C$15="Score as High (5)",5,0),IF(Indicators!$F10="Higher = riskier",1+('Indicator Data'!G10>=Indicators!$G10)+('Indicator Data'!G10>=Indicators!$H10)+('Indicator Data'!G10>=Indicators!$I10)+('Indicator Data'!G10>=Indicators!$J10),1+('Indicator Data'!G10<=Indicators!$G10)+('Indicator Data'!G10<=Indicators!$H10)+('Indicator Data'!G10<=Indicators!$I10)+('Indicator Data'!G10<=Indicators!$J10))) -> 2 | H10: =IF('Indicator Data'!H10="",IF(Config!$C$15="Score as High (5)",5,0),IF(Indicators!$F10="Higher = riskier",1+('Indicator Data'!H10>=Indicators!$G10)+('Indicator Data'!H10>=Indicators!$H10)+('Indicator Data'!H10>=Indicators!$I10)+('Indicator Data'!H10>=Indicators!$J10),1+('Indicator Data'!H10<=Indicators!$G10)+('Indicator Data'!H10<=Indicators!$H10)+('Indicator Data'!H10<=Indicators!$I10)+('Indicator Data'!H10<=Indicators!$J10))) -> 4 | I10: =IF('Indicator Data'!I10="",IF(Config!$C$15="Score as High (5)",5,0),IF(Indicators!$F10="Higher = riskier",1+('Indicator Data'!I10>=Indicators!$G10)+('Indicator Data'!I10>=Indicators!$H10)+('Indicator Data'!I10>=Indicators!$I10)+('Indicator Data'!I10>=Indicators!$J10),1+('Indicator Data'!I10<=Indicators!$G10)+('Indicator Data'!I10<=Indicators!$H10)+('Indicator Data'!I10<=Indicators!$I10)+('Indicator Data'!I10<=Indicators!$J10))) -> 3 | J10: =IF('Indicator Data'!J10="",IF(Config!$C$15="Score as High (5)",5,0),IF(Indicators!$F10="Higher = riskier",1+('Indicator Data'!J10>=Indicators!$G10)+('Indicator Data'!J10>=Indicators!$H10)+('Indicator Data'!J10>=Indicators!$I10)+('Indicator Data'!J10>=Indicators!$J10),1+('Indicator Data'!J10<=Indicators!$G10)+('Indicator Data'!J10<=Indicators!$H10)+('Indicator Data'!J10<=Indicators!$I10)+('Indicator Data'!J10<=Indicators!$J10))) -> 5 | K10: =IF('Indicator Data'!K10="",IF(Config!$C$15="Score as High (5)",5,0),IF(Indicators!$F10="Higher = riskier",1+('Indicator Data'!K10>=Indicators!$G10)+('Indicator Data'!K10>=Indicators!$H10)+('Indicator Data'!K10>=Indicators!$I10)+('Indicator Data'!K10>=Indicators!$J10),1+('Indicator Data'!K10<=Indicators!$G10)+('Indicator Data'!K10<=Indicators!$H10)+('Indicator Data'!K10<=Indicators!$I10)+('Indicator Data'!K10<=Indicators!$J10))) -> 4 | ... AG10: =IF('Indicator Data'!AG10="",IF(Config!$C$15="Score as High (5)",5,0),IF(Indicators!$F10="Higher = riskier",1+('Indicator Data'!AG10>=Indicators!$G10)+('Indicator Data'!AG10>=Indicators!$H10)+('Indicator Data'!AG10>=Indicators!$I10)+('Indicator Data'!AG10>=Indicators!$J10),1+('Indicator Data'!AG10<=Indicators!$G10)+('Indicator Data'!AG10<=Indicators!$H10)+('Indicator Data'!AG10<=Indicators!$I10)+('Indicator Data'!AG10<=Indicators!$J10))) -> 1
